Workbook

Sheet Marcas
A1: Marca | B1: País | C1: Cidade | D1: Principal Característica | E1: Faixa de preço | F1: Preço médio | G1: Site | H1: Instagram | I1: História | J1: Principais relógios | K1: Logo | L1: Site bloqueado | M1: Observações
A2: 1776 Atelier | B2: USA | D2: manufatura independente com foco em relojoaria artesanal moderna | E2: 4 | G2: 1776atelier.com | H2: @1776atelier | I2: A 1776 Atelier foi fundada nos EUA com o propósito de redefinir a alta relojoaria norte-americana — misturando o artesanato tradicional com toques contemporâneos. Cada movimento é desenvolvido com acabamento manual apurado, concebido para ser sinuoso e atemporal. Entre seus modelos icônicos, o Monticello é um destaque notável, exibindo uma sofisticada arquitetura de mostrador esqueleto com numerais romanos e marcadores de horas em forma de estrela, tudo apoiado por um dial texturizado e de impressionante profundidade visual. | J2: Mount Vernon Mount Vernon Aventurine The Monticello
A3: 2CAN | B3: Alemanha | C3: - | D3: modelos de quartz por volta de £30–£35 | E3: 1 | G3: - | H3: - | I3: A 2CAN Professional Timepieces é uma marca alemã que apostou em relógios acessíveis, robustos e de visual esportivo. Com linhas como o Vortex Chronograph (SL1598C CH), a marca entrega design moderno em aço inoxidável escovado e polido, mostradores texturizados sun-guilloché e funcionalidades completas de cronógrafo — minutos, segundos e décimos — além de calendário e bisel ajustável. Os modelos são resistentes à água (5 ATM), utilizam vidro mineral e apresentam caixas de 42 mm com pulseiras de couro de estilo carbono. Há também versões automáticas, encontradas em leilões e coleções, que reforçam a proposta de unir estilo a um preço justo. A filosofia da 2CAN sempre foi oferecer um relógio honesto, funcional e marcante, sem abrir mão da acessibilidade. É a escolha ideal para quem deseja o visual de um cronógrafo profissional, mas dentro de uma faixa de preço democrática. | J3: Vortex Chronograph SL1598C CH SM1597D CH Modelos automáticos raros (vintage)
A4: 2LMX WATCHES | B4: Suíça | C4: Genebra | D4: Manufatura independente de alta relojoaria, conhecida pelos tambores rotativos que substituem mostradores tradicionais | E4: 10 | G4: - | H4: - | I4: A 2LMX Watches nasceu em Genebra pelas mãos de Arnaud Tellier, ex-curador do Museu Patek Philippe, que decidiu transformar sua visão vanguardista em realidade. Criada em 2011, a marca rompeu com a tradição suíça ao apresentar um relógio que aboliu os mostradores convencionais: no lugar deles, tambores rotativos exibem as horas, minutos, segundos e a reserva de marcha, num espetáculo mecânico aberto à contemplação. Produzida em tiragens extremamente limitadas, a 2LMX se consolidou no nicho da haute horlogerie independente, voltada a colecionadores que buscam exclusividade absoluta e design futurista. Cada peça é ao mesmo tempo um instrumento de precisão e uma obra de arte, reafirmando que o tempo pode ser tanto medido quanto admirado. | J4: 2LMX Mechanical Timepiece (edições limitadas com variações de materiais e acabamentos)
A5: 3H Italia | B5: Itália | C5: - | D5: Relógios italianos ultraleves, de design ousado e colorido, com caixas grandes (46–52 mm), equipados com movimentos suíços de quartzo e tratamento luminescente de trítio nos índices e ponteiros. | E5: 2 | G5: marca encontra-se atualmente extinta, sem site funcional | H5: @3hitaliaukwatches | I5: A 3H Italia surgiu com rapidez no cenário europeu, conquistando espaço pela combinação de criatividade, ecletismo, ousadia e tecnologia. Diferente das linhas minimalistas suíças, a marca italiana aposta em cores vibrantes, mostradores marcantes e caixas de grandes dimensões, variando entre 46 mm e 52 mm. O nome “3H” remete ao trítio (³H), material luminescente usado em índices e ponteiros, simbolizando o conceito de leveza e luminosidade. O público-alvo da 3H Italia é formado por pessoas otimistas e cheias de energia, ligadas ao mundo da moda, esportes e vida noturna. Não à toa, celebridades como Shaggy, o cantor Renato Zero e jogadores da seleção italiana, incluindo Leonardo Bonucci, já usaram e declararam seu apreço pela marca. A coleção Ocean Diver reflete bem o DNA da marca, trazendo design moderno, cores chamativas e resistência à água, sempre movida por calibres suíços de quartzo confiáveis.
A6: 47 Zero | B6: França | C6: Chavanod | D6: Microbrand artesanal com mostradores exclusivos, acabamento manual que garante que nenhum relógio seja igual ao outro | E6: 3 | G6: 47zero.com | H6: @the47zero | I6: A 47Zero nasceu nas encostas dos Alpes Franceses, em Chavanod, fundada em 2023 por Cormac Hanley, um irlandês que descobriu a relojoaria durante sua recuperação de um AVC aos 47 anos, o nome “Zero” simboliza um novo começo. Cada relógio 47ZERO é uma obra de arte única: os mostradores são finalizados manualmente, usando técnicas como gravação CNC, laser e polimento artesanal, garantindo que nenhuma peça se repita. O modelo Odd-Hours exemplifica esse espírito, com design assimétrico que desafia convenções e revela detalhes sutis, como parafusos polidos à mão que unem esfera e base do mostrador. Equipados com movimento automático suíço (STP1-11), resistentes até 100 m de profundidade, e disponíveis em 36 mm ou 39 mm, esses relógios entregam uma experiência profundamente pessoal, são menos objetos de status e mais “amuleto líquido de significado”, como descrevem admiradores e colecionadores. | J6: Odd-Hours
A7: 4N Watches | B7: França | C7: Paris | D7: Alta relojoaria contemporânea independente com exibição digital mecânica inovadora por discos giratórios com “jumping hours & minutes” e tiragem extremamente limitada | E7: 10 | G7: 4nparis.com | H7: @4nwatches | I7: A 4N foi fundada em 2009 pelo relojoeiro e designer François Quentin, com o propósito de repensar o modo de exibir o tempo. Movido pela ideia de uma leitura digital totalmente mecânica, inspirada nos mesmos conceitos digitais dos anos 70, Quentin criou o sistema de discos giratórios que mostram as horas e minutos de modo “saltante” (“jumping hours & minutes”). O nome “4N” faz referência aos quatro dígitos utilizados na leitura (tens de horas, horas, dezenas de minutos e minutos). O coração do modelo principal, o 4N-MVT01/D01, é um calibre manual com reserva de marcha de até 10 dias, feito em parceria com a manufatura Renaud & Papi (APRP). A construção é complexa: cerca de 514 componentes, avanço constante de força, acabamento totalmente à mão e ouros compostos e exclusivos, como ouro branco, titânio ou platina, em edições limitadas a 16 unidades. O design é tão técnico quanto estético: caixas robustas e arquitetônicas, mostradores transparentes que revelam o mecanismo, acabamento refinado com alternância entre superfícies polidas e escovadas, e, em alguns casos especiais como o Sapphire Planet, até caixa em safira que revela o movimento em todos os ângulos. | J7: 4N-MVT01/D01 — display digital mecânico por discos, reserva de marcha de 10 dias, edição limitada (16 peças), preços em torno de €150.000
A8: 666 Barcelona | B8: Espanha | C8: Barcelona | D8: Fashion watches com estilo urbano inspirado em Barcelona; design acessível e estético, com display analógico/quartz prático para o dia a dia | E8: 1 | G8: - | H8: - | I8: A 666 Barcelona é uma coleção de relógios com alma urbana, surgida a partir da vibrante atmosfera das Ramblas de Barcelona. Com um visual fashion e urbano, suas peças unem estilo contemporâneo e funcionalidade simples. Disponíveis por preços acessíveis (entre €19 e €29), são ideais para quem busca um acessório com personalidade sem estourar o orçamento. Comercializados principalmente em plataformas online e outlets de moda, esses relógios refletem a estética espanhola moderna — robustos, visualmente charmosos e perfeitos para expressar um estilo cotidiano com atitude. | J8: 666-212, 666-290
A9: 6B Watches | B9: Reino Unido | C9: - | D9: Microbrand artesanal inspirada em relógios militares RAF, com produção limitada, estética funcional e embalagens personalizadas exclusivas | E9: 4 | G9: https://www.gasgasbones.com/ | H9: - | I9: 6B Watches nasceu da paixão de Carl Evans, veterano da Real Força Aérea Britânica (RAF), fundador da marca GasGasBones. Em 2013, após anos lidando com equipamentos militares voltados para funcionalidade no lugar de estética, Carl decidiu materializar sua visão criando o MK1 (uma homenagem aos pilot watches do RAF) em tiragem extremamente limitada com caixa alemã e movimento ETA 7750. O sucesso do MK1 impulsionou a série MK2, com 50 unidades entregues em embalagem elaborada e case de madeira produzido na sede da GasGasBones. Depois, veio o MK3 “Scramble”, de 38 mm, com mostrador militar e embalagem que lembrava um cockpit de Spitfire, incluindo uma caixa "ammo" personalizada com tema operacional. O MKIII Scramble Chronograph, por exemplo, é equipado com movimento Valjoux 7750, vidro de safira antirreflexo, resistência à água de 50 m, acabamento robusto e design pensado para facilitar leitura rápida em ação. A marca é um projeto artesanal e íntimo, Carl desenvolve tudo com honestidade, sem marketing exagerado, com produção pequena e personalização máxima, mantendo sua autenticidade e espírito independente. | J9: MK1 – primeiro modelo, movimento ETA 7750, tiragem de 20 unidades GasGasBones.com MK2 – segunda edição (50 unidades), com embalagens customizadas, straps GasGasBones Hodinkee MK3 “Scramble” – cronógrafo Valjoux 7750, 38 mm, série limitada, embalagens inspiradas em aviões Spitfire
A10: 88 Rue Du Rhone | B10: Suíça | C10: Genebra | D10: Relógios suíços contemporâneos com estética de luxo acessível, design elegante (como mostradores com o “Double 8”), opções em quartzo e automáticos, voltados para um público jovem que busca estilo sem abrir mão da qualidade | E10: 2 | G10: marca encontra-se atualmente extinta, sem site funcional | H10: @88rdr | I10: Criada em 2012 pelos irmãos Pierre e Elie Bernheim — netos do renomado relojoeiro Raymond Weil — a 88 Rue Du Rhone nasceu em Genebra com a ambição de democratizar a relojoaria suíça. O nome evoca a famosa Rua do Ródano, símbolo de elegância no centro da cidade, e o "Double 8" usado no logo traz consigo simbologias de sorte e infinito, reforçando a identidade da marca Wikipedia jurawatches.co.uk . A missão era clara: oferecer relógios de qualidade suíça, com visual sofisticado e preços acessíveis a um público mais jovem, entre os US$ 395 e US$ 995 — muito abaixo do padrão tradicional da alta relojoaria Worn & Wound . Modelos como os da linha Double 8 Origin combinaram mostradores texturizados, cristais brilhantes e detalhes refinados, mantendo a excelência dos mecanismos, em versões quartzo e automáticas. Apesar de todo o sucesso inicial, a marca acabou encerrando suas operações em 2020 após dificuldades financeiras. Ainda assim, permaneceu como um marco significativo na história recente da relojoaria suíça acessível, deixando na memória peças com identidade e charme atemporal | J10: Double 8 Origin
A11: A. Lange & Söhne | B11: Alemanha | C11: Glashütte | D11: Alta relojoaria alemã de manufatura, com movimentos próprios de precisão excepcional, acabamento artesanal refinado e design austero (estilo “teutônico”) | E11: {=INDEX('Tabela de faixa de preços'!$A$1:$A$10,MATCH(1,('Tabela de faixa de preços'!$B$1:$B$10<=F11)*('Tabela de faixa de preços'!$C$1:$C$10>=F11),0))} | F11: 355000 | G11: alange-soehne.com | H11: @alangesoehne | I11: Fundada em 1845 por Ferdinand Adolph Lange em Glashütte, na Saxônia, com a missão de transformar uma região empobrecida num polo de alta relojoaria alemã. A dinastia prosperou por gerações até ser silenciada pela Segunda Guerra e pela posterior estatização na Alemanha Oriental. A marca renasceu em 1990 pelas mãos de Walter Lange, bisneto do fundador, dias após a queda do Muro de Berlim. Coleções como a Lange 1 — com seu icônico calendário grande e o mostrador assimétrico segundo a proporção áurea —, além de Datograph, Zeitwerk, Saxonia e Odysseus, definiram a nova era. É referência absoluta em acabamento: pontes em prata alemã (Neusilber), balanço com parafusos de ouro e o galo do balanço gravado à mão, peça a peça. Cada movimento é montado, ajustado, desmontado e remontado antes da entrega. Virou símbolo do orgulho relojoeiro alemão. [⚠️ verificar dados atuais] | J11: Lange 1, Datograph, Zeitwerk, Saxonia, Odysseus
A12: A. Manzoni & Fils | B12: Suíça | C12: Lugano | D12: Manufatura suíça revivida com design contemporâneo e complicações de calendário semanal (week planner) | E12: 7 | I12: Fundada em 1888 em Arogno (Lugano), a A. Manzoni & Fils ganhou nova vida em 2010 quando Oliver Ike (cofundador da Ikepod) reativou a marca com o designer Ilkka Suppanen. O Canopus Weekplanner (2013) virou assinatura: mostra hora, dia, data, semana do ano e fase da lua, usando módulo Dubois-Dépraz sobre calibre Soprod A10. O projeto combinou estética “retro-futurista” (caixa curva, mostrador multicamadas) com produção Swiss Made em séries curtas. | J12: Canopus Weekplanner
A13: AATOS | B13: China | C13: - | D13: Tourbillon mecânico acessível, marketing agressivo pelo menor preço possível, mas com questionamentos sobre autenticidade e qualidade | E13: 2 | G13: - | H13: - | I13: A AATOS é conhecida por seu ousado posicionamento: oferecer um tourbillon mecânico por menos de £400, um valor que surpreende mesmo dentro do nicho de entrada da relojoaria. O modelo mais falado é o Tiago, um relógio de 42 mm com mecanismo aparentando ser um tourbillon real. No entanto, sua procedência é nebulosa — alguns críticos sugerem que seu DNA pode ser chinês, com qualidade e marketing duvidosos. Ainda assim, despertou curiosidade no mundo relojoeiro como uma proposta inacreditavelmente barata por uma complicação tradicionalmente cara. | J13: Tiago (LSB 42 mm)
A14: Abingdon | B14: USA | C14: Las Vegas | D14: Relógios funcionais e estilizados, desenhados por uma piloto para mulheres ativas; incluem funcionalidades como taquímetro, múltiplos fusos, cronógrafo, bússola e calculadora de voo (“E6B”), com design robusto e moderno | E14: 2 | G14: abingdonco.com | H14: @theabingdonco | I14: Abingdon Co. foi fundada em 2007 por Chelsea Abingdon Welch (Mullin), uma piloto que percebeu a ausência de relógios de aviação projetados para mulheres. Com paixão e visão, ela criou modelos como Jackie e Amelia, lançados em 2007, produzidos inicialmente em Hong Kong. Em 2010, a sede foi transferida para Las Vegas, onde a marca continua inovando a cada coleção. Seu catálogo evoluiu para incluir relógios de mergulho, aviação, corrida e uso militar, todos com funcionalidades práticas como régua de cálculo E6B (útil em caso de pane nos instrumentos de voo), bússola, cronógrafos e resistência à água, aliados a um design pensado para uso real. A Abingdon Co. hoje é reconhecida por empoderar mulheres que desafiam estereótipos e exercem profissões ativas — piloto, mergulhadora, engenheira ou exploradora urbana Wikipedia The Abingdon Co. Worn & Wound Girls that Scuba . Em 2025, a marca inaugurou sua flagship store em Las Vegas e continua atuando como timekeeper oficial de eventos como o Air Race Classic — prova de seu reconhecimento no universo feminino e da aviação | J14: Amelia, Jackie, Marina, Jane, Jordan, Katherine, Nadia, Legends
A15: About Vintage | B15: Dinamarca | C15: Copenhague | D15: Microbrand nórdica que combina design vintage escandinavo minimalista com movimentos confiáveis (Seiko/Miyota e suíços), embalagens refinadas com a silhueta de Copenhague gravada na tampa | E15: 2 | G15: aboutvintage.com | H15: - | I15: Fundada por dois amigos dinamarqueses — Thomas Gyvelgaard Andersen e Sebastian Skov Regeser — em 2013, a About Vintage nasceu com a proposta de reinterpretar clássicos da relojoaria com um olhar moderno e minimalista Independent Watch Brand Addict . Cada modelo leva um nome ligado a um momento marcante da história da relojoaria, como “1815”, “1926”, “1956”, acrescentando poesia à sua estética. Os relógios são cuidadosamente embalados em caixas de madeira com fechamento magnético e a silhueta de Copenhague gravada na parte interna da tampa — cada peça numerada e com assinatura de origem Hype & Style Tick Tock Shop . O design busca equilíbrio entre simplicidade vintage e toques contemporâneos, enquanto os movimentos — automáticos Seiko ou com calibres suíços — garantem confiabilidade e acessibilidade Hype & Style WatchReport.com +1 . A combinação de refinamento estético, cuidado artesanal visual e preço equilibrado transformou a marca numa referência entre os dress watches inspirados no estilo vintage, ideais para quem quer elegância acessível sem abrir mão de personalidade. | J15: 1815 Chronograph — cronógrafo quartz, cerca de €349 (≈ R$ 2.000) AV86 1926 At’ Sea Diver — relógio estilo diver com calibre Seiko VH31, preço por volta de US$ 399 (≈ R$ 2.100) WatchReport.com 1956 Marine — diver vintage com bezel cerâmico e Miyota automático, partindo de US$ 449 (≈ R$ 2.350)
A16: Accutron | B16: USA | C16: Nova York | D16: Marca pioneira da relojoaria eletrônica com tecnologia de diapasão e, hoje, movimentos eletrostáticos modernos que unem inovação tecnológica e legado histórico | E16: {=INDEX('Tabela de faixa de preços'!$A$1:$A$10,MATCH(1,('Tabela de faixa de preços'!$B$1:$B$10<=F16)*('Tabela de faixa de preços'!$C$1:$C$10>=F16),0))} | F16: 16000 | G16: accutronwatch.com | H16: - | I16: A Accutron surgiu em 1960 como uma revolução: o primeiro relógio de pulso totalmente eletrônico — utilizando um diapasão de 360 Hz em vez do tradicional balanço — desenvolvido por Max Hetzel e produzido pela Bulova em Nova York Bulova Australia Wikipedia +1 accutronwatchpage.com . A precisão era impressionante: ±2 segundos por dia, superior à dos mecânicos da época. Esse diferencial fez da Accutron a escolha da NASA, com componentes utilizados em missões espaciais como o Apollo e o Mercury, assim como na superfície lunar durante a Apollo 11 e até relógios de bordo windupwatchshop.com . Após a descontinuação da vibração por diapasão, a marca foi reativada em 2020 como uma entidade independente pelo grupo Citizen. As novas linhas incluem o Spaceview 2020 e o Accutron DNA, movidos por tecnologia inovadora de indução eletrostática, trazendo o DNA futurista da marca à era moderna | J16: Vintage Accutron Spaceview (1960s) — pioneiro do diapasão, visual icônico de mostradores abertos Accutron Spaceview 2020 — reeditação moderna com mecanismo eletrostático Accutron DNA / Evolution — tecnologia futurista, visual contemporâneo
A17: Acto | B17: Brasil | C17: Porto Alegre | D17: Marca independente brasileira de design autoral, com colaborações criativas e especificações de produto bem equipadas (safira, 10 ATM, Super-Luminova, Miyota) em séries curtas | E17: 3 | F17: 3500 | G17: actowatches.com | H17: @acto | I17: Fundada em 2020, a Acto surgiu em Porto Alegre com a proposta de criar relógios de identidade própria — menos “white-label”, mais estética brasileira contemporânea. Ao lado de artistas e designers convidados, a marca foi ganhando tração no mercado local, mantendo comunicação direta e produção em séries limitadas | J17: AC01 (Bourbon, Urban, Outlander, Navigator, Phantom) — R$ 5.970. ACTO AD01 (diversas cores) — R$ 6.730 (algumas edições especiais até R$ 8.790). ACTO +1 PB012 (by Patrícia Bonaldi) — R$ 9.700. ACTO A003 Carbon (by Erich Shibata) — R$ 11.970 (topo pontual). ACTO AS01 Angra (edição limitada) — R$ 4.850 (abaixo da média da marca). ACTO +1 A001 — R$ 3.500
A18: ADPT | B18: USA | C18: - | D18: Marca de lifestyle outdoor que evoluiu de acessórios (pulseiras têxteis) e lançou um relógio multipropósito leve e colorido com caixa de titânio, movimento automático Seiko NH34 e visual exclusivo | E18: 2 | G18: ADPTGoods.com | H18: @adptgoods | I18: ADPT (pronunciado “adapt”) foi fundada em 2017 pelos criadores do Worn & Wound, como uma marca dedicada inicialmente a fabricar pulseiras de nylon mil-spec feitas nos EUA. Com o tempo, se expandiu para oferecer uma linha completa de acessórios e, em 2022, estreou seus primeiros relógios com o Series 1 — esportivo, titaniumado, 200 m de resistência, mostrador texturizado e cores vibrantes, inspirado no outdoor e no universo EDC (Everyday Carry) Island Watch Worn & Wound +1 Fratello Watches . O modelo Series 1 Dual-Time manteve a robustez do original e acrescentou uma complicação GMT (indicador 24 h) movimentada pelo calibre Seiko NH34, mantendo o DNA funcional da marca com forte identidade visual | J18: Series 1 — field watch leve em titânio, 200 m, Seiko NH35, visual colorido Series 1 Dual-Time — funcionalidade GMT com o novo Seiko NH34, mesmas linhas outdoor e modernas Colaborações — edição limitada com VERO (Workhorse Chronograph), consolidando seu status no mundo outdoor e horológico aventureiro | K18: https://windupwatchshop.com/cdn/shop/t/41/assets/adpt-brand-logo.svg?v=137860177147247661051761747591
A19: Adriano Valente | B19: Suíça | C19: Lausanne | D19: Relojoaria de luxo personalizável inspirada nos supercarros italianos, com caixa angular em materiais como Karbonyte, AlTiCar ou magnésio forjado e mostrador que imita um velocímetro | E19: 8 | G19: - (adrianovalente.com, hoje inativo para a marca) | H19: - | I19: A Adriano Valente foi criada por volta de 2010 em Lausanne, na Suíça, por um fundador italiano que não encontrava no mercado o relógio que queria — por isso a personalização virou o centro da proposta. Em 2011 a marca apresentou seu único modelo, o AV-L001, pensado para combinar com uma Lamborghini: caixa angular mais larga que alta, mostrador inspirado no velocímetro, centro que lembra as entradas de ar hexagonais do Murciélago e coroa desenhada como uma roda com freio a disco. Não havia nenhuma parceria oficial com a montadora; a inspiração era apenas estética. O cliente escolhia o material da caixa (Karbonyte, AlTiCar ou magnésio forjado), a cor da caixa — podia ser igual à pintura do próprio carro —, mostrador, pulseira de borracha ou Alcantara, coroa e fundo aberto ou fechado. Pagando à parte, era possível "travar" a combinação para que ninguém mais tivesse um igual. O movimento automático Engine-001A trazia grande data saltante e indicador de reserva de marcha, e o preço partia de 32.500 francos suíços. Depois do lançamento a marca praticamente desapareceu: não há novos modelos nem notícias, e o antigo site hoje pertence a outra pessoa. | J19: AV-L001 — único modelo (2011), movimento Engine-001A com grande data e reserva de marcha, caixa em Karbonyte/AlTiCar/magnésio, 6 cores com nomes no estilo Lamborghini (Nero Tartarus, Giallo Hyperion, Rosso Eos, Grigio Menoetius, Bianco Ophian, Verde Icaria) | K19: https://www.fashionbi.com/rails/active_storage/blobs/redirect/eyJfcmFpbHMiOnsiZGF0YSI6MTg4NCwicHVyIjoiYmxvYl9pZCJ9fQ==--3e6fde9bff4b1ee1abfaa5145820cb739e3a2e61/Adriano%20Valente-logo.jpeg
A20: Aera | B20: Suíça/Reino Unido | C20: Genebra | D20: Microbrand de tool watches contemporâneos com design minimalista e curvas suaves, usando caixa em aço 904L, acabamento suíço e movimentos Sellita | E20: {=INDEX('Tabela de faixa de preços'!$A$1:$A$10,MATCH(1,('Tabela de faixa de preços'!$B$1:$B$10<=F20)*('Tabela de faixa de preços'!$C$1:$C$10>=F20),0))} | F20: 15000 | G20: aera.co | H20: @aerainstruments | I20: A Aera nasceu em 2018, em Genebra, como resultado da parceria entre Jas Minhas e Olof Larsson — veteranos da indústria relojoeira. Movidos por paixão e legado (Minhas com raízes watchmakers e Larsson com histórico de retail), a dupla criou relógios que fossem minimalistas, funcionais e ao mesmo tempo contemporâneos Hodinkee Oracle Time . Com design inspirado nos archetypes dos tool watches — mas reinterpretados com silhuetas suaves, curvas e dials côncavos — Aera lançou modelos como os P-1 Pilot e D-1 Diver, ambos com acabamento em aço 904L, calibres Sellita suíços, e estética limpa e legível Uncrate Hodinkee +1 . A marca se posiciona na interseção entre acessibilidade, design de vanguarda e engenharia tradicional. | J20: P-1 Pilot — tool-watch com movimento Sellita SW200-1, caixa em 904L, mostrador legível, disponível por ~US$ 1.300 (~R$ 6.500) Silodrome D-1 Diver — relógio de mergulho com bezel unidirecional, estilo moderno minimalista Uncrate C-1 Chronograph (Shadow / Cloud) — cronógrafo bicompax com design limpo e movimento Sellita SW51 | K20: https://aera.co/cdn/shop/files/Aera_Logo.png?v=1614349956 | XFD20: ;
A21: Aeromat | B21: Suíça | C21: - | D21: Relógios de aviação contemporâneos (tool watches) com alta legibilidade, uso de materiais técnicos (para-carbono, aço 904L), movimentos suíços/quartz modernos e design inspirado em instrumentos de voo | E21: 2 | G21: aeromatwatches.com | H21: @aeromat_official | I21: Aeromat nasceu da paixão de um grupo de entusiastas por relógios de piloto, com o objetivo de trazer inovação ao gênero. Com coleções como a AEM 450 (inspirada em exigências de pilotos modernos), Airspeed (ensaio estético nas linhas clássicas da Havilland) e o PNY (cronógrafo retrô dos anos 50), a marca se consolidou como referência entre os apaixonados por relógios de aviação acessíveis. A linha VDN homenageia pilotos noturnos e eleva o conceito de tool watch com funcionalidade real para voos | J21: VDN (Vol de Nuit): cronógrafo para voos noturnos, preço ~US$ 490–520 (~R$ 2.600–2.800) AEM 450 / AEM Pilot Edition: relógico leve com case de carbono, ~US$ 490 (~R$ 2.600) PNY: cronógrafo retrô, preço similar (~US$ 480 → R$ 2.600) Airspeed: automático estiloso, preço ~US$ 790 (~R$ 4.300) Beluga: automático robusto, ~US$ 990 (~R$ 5.400) IFR: tool quartz com calculadora de voo, | K21: https://www.aeromatwatches.com/web/image/website/6/logo/Aeromat%20Watches?unique=ee218df
A22: Aeronom | B22: Alemanha | C22: - | D22: Estilo street / urbano robusto com inspirações heavy (cases grandes, bezel agressivo, linhas que lembram relógios “peso-bruto”), acabamento foco em detalhes como índices luminescentes, coroa rosqueada, vidro de safira, resistência de 100m. Marca independente voltada para estética audaciosa com automáticos acessíveis. | E22: 2 | G22: aeronom-watches.com | H22: @aeronom_watches | I22: A Aeronom se apresenta como uma marca para quem gosta de relógio que “faz presença”. Fundada por entusiastas alemães, sua filosofia é tornar “o relógio dos seus sonhos” realidade — mas não um relógio pequeno ou discreto. O modelo Aero One — a cara da marca — é automático, pesado no visual, ousado no design, com bezel grande, índices e mostradores impactantes, tudo pensado para estilo urbano porte grande. Projetado para resistência mínima de uso diário (100m) e construção em aço (316L) com vidro de safira, o Aero One combina robustez com estilo que chama atenção. | J22: Aero One — referência principal da marca; edições como “Big Panda”, “BLK” entre outras; preço ~ €495 (automático com Miyota 8217) AERONOM® +1 Edições limitadas do Aero One (por exemplo, “BLK”, “Panda” etc.) com detalhes de cores e acabamento diferenciados | K22: https://aeronom-watches.com/assets/img/aeronom_logo_w_t.png
A23: Aerowatch | B23: Suíça | C23: La Chaux-de-Fonds | D23: Marca suíça familiar independente, especializada em relógios clássicos e também em relógios de bolso, com estética elegante e complicações acessíveis | E23: 2 | F23: 8000 | G23: aerowatch.com | H23: @aerowatch | I23: A Aerowatch foi fundada em 1910 em La Chaux-de-Fonds, coração da relojoaria suíça, inicialmente focada em relógios de bolso e de pendente. A empresa permaneceu independente ao longo das décadas, passando por gerações da família Crevoisier até chegar à gestão da família Bolzli. Hoje está sediada em Saignelégier, mantendo produção de relógios elegantes com design clássico e mecânica confiável. O catálogo inclui tanto modelos contemporâneos quanto homenagens vintage, mas sempre com a herança da tradição suíça presente. A Aerowatch é especialmente lembrada por seu equilíbrio entre qualidade, design refinado e preço acessível, sendo uma escolha para quem busca sofisticação sem entrar nas cifras mais altas da alta relojoaria. | J23: Les Grandes Classiques — coleção tradicional com design elegante Streamline — linhas modernas com identidade própria 1942 Collection — estética vintage inspirada na década de 40 Pocket Watches / Lepines — continuidade do legado original em relógios de bolso | K23: https://www.aerowatch.com/pub/static/version1765335430/frontend/Procab/aero/en_US/images/logo.svg
A24: Aesop | B24: China | C24: Guangzhou | D24: Marca chinesa de Guangzhou especializada em tourbillons mecânicos de baixo custo e relógios de moda, muito difundida em marketplaces online | E24: 2 | G24: aesoptourbillon.com | H24: @aesoptourbillonofficialstore | I24: A Aesop tem raízes na indústria relojoeira de Guangzhou, na região próxima a Hong Kong, e se estabeleceu como marca própria no início dos anos 2000. Nasceu para levar a estética do tourbillon — normalmente reservada à alta relojoaria — a um público que jamais poderia pagar por ela. O posicionamento é claro: oferecer relógios mecânicos de aparência luxuosa, com destaque para tourbillons esqueletizados e linhas de quartzo masculinas e femininas, vendidos sobretudo por AliExpress, Amazon e lojas de dropshipping. O apelo é a 'complicação impossível' a preço acessível. Divide opiniões entre entusiastas: para alguns é porta de entrada divertida ao mundo mecânico; para outros, exemplo do tourbillon 'decorativo' chinês. De todo modo, ocupa um nicho real de moda relojoeira de massa. [⚠️ verificar dados atuais: fundação, sede exata e catálogo] | J24: Aesop Tourbillon Skeleton, linhas de quartzo masculino e feminino
A25: Aether | B25: USA | C25: Phoenix | D25: Microrrelojoaria americana de relógios sociais de corda manual, com caixa feita em Pforzheim (Alemanha), movimento Unitas 6498 decorado e pulseiras artesanais da Stone Creek Straps | E25: 3 | G25: aetherwatches.com | H25: @aetherwatches | I25: A Æther Watch Co. foi criada em 2012 em Phoenix, no Arizona, pelos donos da Stone Creek Straps, fábrica americana de pulseiras artesanais de couro. A ideia era levar para o relógio o mesmo cuidado artesanal das pulseiras: desenho em Phoenix, caixa e montagem em Pforzheim, na Alemanha, berço da relojoaria alemã. O primeiro e principal modelo foi o AE01, um relógio social de 42 mm com movimento de corda manual Unitas 6498, acabamento Côtes de Genève e parafusos azulados, oferecido com mostradores preto fosco, antracite escovado, marrom escovado, prateado e carmim, além de versão com caixa em ouro rosé. Custava entre US$ 1.350 e US$ 1.500. Em seguida veio a Æther by Jochen Benzinger, edição especial de apenas 25 peças em que o movimento foi redecorado à mão pelo gravador alemão Jochen Benzinger, com guilhoché cortado à mão e balanço gravado banhado a ouro rosé, por cerca de US$ 3.900. Desde meados da década de 2010 a marca não apresentou novos modelos. Atenção: não confundir com a Aether Apparel, marca de roupas outdoor de Los Angeles que em 2023 lançou o relógio Aether + Bamford GMT — é outra empresa. | J25: AE01 — social de corda manual, 42 mm, Unitas 6498 decorado, mostradores preto, antracite, marrom, prateado e carmim (também em ouro rosé) Æther by Jochen Benzinger — edição especial de 25 peças com movimento decorado à mão
A26: Aethia | B26: USA | C26: San Francisco | D26: Microbrand americana de relógios esportivos leves em titânio, com design disruptivo voltado a atividades outdoor e a um público de adrenalina | E26: 2 | G26: aethiawatch.com | H26: @aethiawatchcompany_usa | I26: A Aethia Watch Company nasceu nos Estados Unidos com a proposta de romper tendências e criar designs disruptivos para entusiastas — dos novatos aos colecionadores experientes. Em 2025 mudou a sede para San Francisco, consolidando sua identidade em torno de performance e esportes. Seu primeiro protótipo foi o Activa, relógio esportivo leve em titânio pensado para atividades ao ar livre. Depois veio o PULSIQ (2025), com diversas variantes e melhorias, movendo a linguagem da marca para uma estética de velocidade e adrenalina, reforçada por embaixadores atletas multiesportivos. Como microbrand jovem, aposta em titânio, leveza e visual arrojado como diferenciais frente às marcas outdoor tradicionais, buscando espaço num segmento dominado por nomes consagrados. [⚠️ verificar dados atuais: ano de fundação e fundador] | J26: Activa, PULSIQ | K26: https://aethiawatch.com/cdn/shop/files/LogoWhite.png?v=1700045446
A27: Airain | B27: França | C27: Besançon | D27: Marca militar francesa histórica (1934), revivida em 2020, fiel ao cronógrafo flyback Type 20 da aviação militar francesa | E27: 4 | G27: airain.com | I27: Fundada em 1934 e ligada à célebre dinastia relojoeira francesa Dodane, a Airain teve papel importante na era de ouro dos cronógrafos de aviação militar da França nos anos 1950 e 1960. Foi uma das fornecedoras selecionadas para o Type 20 da Força Aérea, ao lado de nomes como Breguet, Auricoste e Vixa. O Type 20 seguia a especificação militar dos anos 1950: cronógrafo robusto com função flyback, que permitia ao piloto reiniciar a cronometragem instantaneamente sem parar antes. Em 2020 a marca foi revivida por Tom van Wijlick (também por trás da Lebois & Co.), fiel ao conceito original. A reedição trouxe manufatura suíça, cristal de safira e um flyback de roda de colunas da Manufacture AMT, mantendo as especificações militares. A Airain reconquistou até lugar nos pulsos dos pilotos da ALAT francesa. Hoje a marca pertence à Compagnie des Montres Lebois & Cie (CDMLEC), empresa de Tom van Wijlick sediada em Reuver, na Holanda, e os relógios são produzidos na Suíça. | J27: Type 20, Type 21, Sous-Marine (mergulho, reedição do modelo de 1962), Voyageur GMT (2025) | K27: https://www.airain.com/wp-content/uploads/2022/06/LOGO_AIRAIN_def-500x200-1.png
A28: Aision | B28: Hong Kong | C28: Hong Kong (Tsim Sha Tsui) | D28: Microbrand de design minimalista, focada em estética depurada e nos detalhes mais sutis | E28: 2 | G28: aisiondesign.com | I28: A Aision Design é uma microbrand relojoeira construída sobre uma filosofia de design baseada no essencial. Sua missão declarada é apresentar uma estética única por meio do design e da produção, encontrando beleza nos menores detalhes. O mundo ao redor serve como fonte constante de inspiração para a marca, que traduz esse olhar em peças minimalistas e depuradas. As informações públicas ainda são escassas, o que é típico de microbrands em fase inicial. Como muitas marcas independentes emergentes, aposta na identidade visual limpa e no apelo direto ao consumidor pela internet. A AISION Design é de Hong Kong e tem como designer Lee Cheuk Chung. Estreou em 2018–2019 com o AN-S01, um automático de inspiração espacial lançado no Kickstarter, seguido em 2020 dos AN-S03 (hora em discos) e AN-S04, com caixa de 45 mm e visual de "OVNI". Hoje o catálogo gira em torno da série HANG (incluindo o mergulhador HANG Abyssus, o HANG GMT e a linha artesanal HANG Crafts com folha de ouro e prata), do KONG, do NGIZED Layer-0 de mostrador "suspenso", do CMYK e de três famílias de tourbillon (AN-T01, AN-T02 e AN-T03), muitas com mostradores de pedras como meteorito, charoíte e pietersita. | J28: HANG / HANG Abyssus (mergulho) / HANG GMT / HANG Crafts — automáticos com mostradores de pedra, esmalte e madrepérola Tourbillon AN-T01, AN-T02 e AN-T03 NGIZED Layer-0, KONG, CMYK AN-S01, AN-S03 e AN-S04 — primeiros modelos de inspiração espacial (2019–2020)
A29: Aittokoski Timecrafts Fractalis | B29: Finlandia | C29: Jyväskylä | D29: Relojoaria independente finlandesa de Timo Aittokoski, engenheiro que aplica soluções construtivas não convencionais às caixas e mostradores | E29: {=INDEX('Tabela de faixa de preços'!$A$1:$A$10,MATCH(1,('Tabela de faixa de preços'!$B$1:$B$10<=F29)*('Tabela de faixa de preços'!$C$1:$C$10>=F29),0))} | G29: aittokoski.watch | I29: A Aittokoski Timecrafts é uma marca independente de Jyväskylä, na Finlândia central, fundada por Timo Aittokoski — doutor em ciência da computação e mestre em ciência do esporte, com raízes fincadas no interior finlandês. Antes dos relógios, ele já projetava motos turbinadas, motores dois-tempos de competição, dinamômetros e eletrônica de controle. Depois de uma busca frustrada pelo 'relógio dos sonhos', Aittokoski passou três anos desenvolvendo sua estreia, o Fractalis, lançado em 2019. A peça mistura tradição e futurismo: cristal protegido por bezel, fundo que não rotaciona, lugs-compressores intercambiáveis que unem bezel, caixa e fundo, e um mostrador maciço em aço. O portfólio evoluiu para os modelos Fractalis, R-27 e Quantalor, todos marcados pela mentalidade de engenheiro e por soluções mecânicas fora do convencional. O Fractalis tem caixa de 42 mm × 10 mm com movimento ETA 2892-A2 e é oferecido em aço 316L, "super aço" 2205 ou titânio, inclusive na versão Carbon Black com mostrador de cobre maciço. O R-27 traz caixa hexagonal inspirada em favos de mel, com mostradores Deepest Black ou Arctic Steel e opção de PVD preto. O Quantalor, à venda desde setembro de 2023, tem as versões Glacial Steel e Black Moon. Todos podem ser personalizados com gravações. | J29: Fractalis, R-27, Quantalor | K29: https://static.wixstatic.com/media/a512cf_34a398ba1fbb459299bbfccec73f188f~mv2.png
A30: Akerfalk | B30: Suécia | C30: Karlstad | D30: Microbrand sueca de relógios de 24 horas, com minimalismo escandinavo e pulseiras em couro Horween | E30: 2 | G30: akerfalk.se | I30: A Akerfalk é uma microbrand sueca que fez do relógio de 24 horas sua marca registrada, traduzindo o minimalismo escandinavo em peças de design limpo, equilibrado e atemporal. A proposta une simplicidade nórdica a preços acessíveis, com venda direta ao consumidor. Estreou com o modelo First Season, sua leitura contemporânea do minimalismo, e depois expandiu a linha: o Second Season reduziu a caixa de 40 mm para 36 mm, tornando-o unissex; o Chronograph adotou movimento meca-quartz Seiko VK-64 com subdial de 24 horas; e o Äventyr trouxe novos acabamentos. As pulseiras são feitas em couro Horween 100%, que ganha caráter com o tempo. Com alguns anos de estrada, frete global grátis e dois anos de garantia, a marca firmou seu nicho de design escandinavo acessível. A marca foi fundada em 2016 em Karlstad, na Suécia, por três amigos vindos da moda — Mikael Söderberg, Joakim Lidbäck e Anders Lipkin — e lançou seu primeiro relógio por financiamento coletivo no Indiegogo em 2017. Os relógios usam movimentos suíços Ronda e couro americano Horween, com caixas prata, dourada ou preta fosca. A novidade mais recente é o Mecha Quartz. | J30: First Season — 24 horas, 40 mm, caixa prata, dourada ou preta Second Season — 24 horas, 36 mm, unissex Chronograph 12h/24h — meca-quartz Seiko VK-64 (Panda, Lake, Forrest) Äventyr 24-Hour (Vanta Black, Dull Steel) Mecha Quartz (lançamento mais recente)
A31: Akhor | B31: Suíça | C31: Meyrin | D31: Alta relojoaria independente de Genebra (2025), com mostrador de discos sobrepostos patenteado e certificação Poinçon de Genève | E31: 8 | G31: akhor.ch | I31: A Akhor é uma das mais jovens manufaturas a entrar no círculo da alta relojoaria independente: estreou no Geneva Watch Days de 2025, fundada naquele ano em Genebra (Meyrin) por Anissa Bader, cofundadora e CEO, também presidente da Clamax — fornecedora de componentes de movimento da região de Genebra que é a parceira de produção da marca e detém a patente do mostrador de dois níveis. Nasceu ao redor de uma ideia poética — o 'tempo em equilíbrio' — e de uma visão bastante original do próprio tempo. Sua coleção de estreia, a Le Temps en Équilibre, traz a assinatura da marca: uma arquitetura de mostrador de discos duplos patenteada, em que os ponteiros de horas e minutos giram sob a placa superior e se revelam apenas parcialmente, como suspensos em movimento. A caixa cushion de 39 mm vem em ouro ou aço, e a Nour la Lumière acrescenta um terceiro disco com indicação dia/noite. No coração bate o calibre AK10, de corda manual, 4 Hz e 60 horas de reserva, desenvolvido com apoio do consultor Daniel Martinez. Toda a coleção carrega o Poinçon de Genève — a mais alta distinção suíça — além de certificação COSC. Os preços partem de CHF 28 mil. O catálogo já soma mais de 20 versões do AK-10: em aço (CHF 28.800), aço com 120 diamantes na luneta (a partir de CHF 38.800), ouro 4N/5N (CHF 57.800) e ouro com diamantes, com mostradores raiados ("sunburst") ou em favo de mel ("honeycomb") e, desde 2026, discos em pedras como maw sit sit, estromatólito, jaspe e cianita. No topo estão os Nour La Lumière em ouro e platina (CHF 198 mil e 208 mil), com gravação à mão e pintura em miniatura de um dromedário nas dunas. | J31: Le Temps en Équilibre AK-10 — aço, aço com diamantes (AK-10-D) e ouro (AK-10-AU), mostradores sunburst ou honeycomb AK-10 em pedras ornamentais — Maw Sit Sit, Stromatolite, Deschutes Jasper, Yellow Kyanite, Ruby Heart, Tiger Iron Nour La Lumière (AK-10-AU-JN / AK-10-PT-JN) — dia/noite com terceiro disco, gravação e pintura em miniatura | K31: https://akhor.ch/akhor-logo.svg?v=2
A32: Akrivia | B32: Suíça | C32: Genebra | D32: Alta relojoaria independente de Rexhep Rexhepi, com acabamento artesanal excepcional no estilo da escola genebrina clássica | E32: {=INDEX('Tabela de faixa de preços'!$A$1:$A$10,MATCH(1,('Tabela de faixa de preços'!$B$1:$B$10<=F32)*('Tabela de faixa de preços'!$C$1:$C$10>=F32),0))} | F32: 1000000 | G32: rexheprexhepi.com (antigo akrivia.com) | I32: A Akrivia foi fundada em 2012 em Genebra por Rexhep Rexhepi, relojoeiro de origem kosovar que emigrou criança para a Suíça e se formou nas oficinas de Patek Philippe e BNB Concept antes de abrir a própria manufatura ainda muito jovem. O nome vem do grego para 'precisão' e 'exatidão'. De peças complexas iniciais, Rexhepi migrou para uma linguagem de sobriedade clássica com o Chronomètre Contemporain, celebrado por unir mostrador em esmalte grand feu, acabamento à moda antiga e uma pureza estética que o tornou um dos independentes mais desejados do mundo. O ateliê ocupa a histórica Vieille Ville de Genebra. Cada relógio é montado à mão em séries mínimas, com acabamentos feitos segundo técnicas do século XIX — chanfros polidos à mão, pontes graníteas, cabeças de parafuso polidas em espelho. Virou símbolo do renascimento da alta relojoaria artesanal independente. A primeira fase da marca (Chapter I) foi a dos tourbillons numerados de AK-01 a AK-05, entre 2012 e 2016, seguidos do AK-06 em 2017, primeiro modelo sem tourbillon. Em 2018 nasceu a linha assinada "Rexhep Rexhepi" com o Chronomètre Contemporain (RRCC), seguido em 2022 do RRCC II em ouro rosa e platina (50 peças cada). Vieram ainda o Chronomètre Antimagnétique, peça única para o Only Watch 2023 (cerca de US$ 2,3 milhões), o LVRR-01 Chronographe à Sonnerie com a Louis Vuitton (2023) e, em 2026, o Chronograph Flyback RRCHF (CHF 150 mil). A produção gira em torno de 50 relógios por ano, vendidos por lista de espera, e o site oficial hoje é rexheprexhepi.com. | J32: Chronomètre Contemporain (RRCC) e RRCC II — esmalte grand feu, segundos mortos Chronograph Flyback RRCHF (2026) LVRR-01 Chronographe à Sonnerie (com Louis Vuitton) AK-01 a AK-05 — tourbillons; AK-06 | K32: https://maj.akrivia.com/wp-content/themes/akrivia/assets/images/logo_akrivia_lplv.svg
A33: Akrone | B33: França | C33: Nantes | D33: Manufatura francesa independente que cria relógios automáticos com produção local em Nantes, parceria com elite militar francesa e proposta de "Made in France" | E33: 2 | F33: 2500 | G33: akrone.fr | H33: @akrone_official | I33: Fundada em 2015 em Nantes por Jean-François Kerboul e Erwan Kerneur, a Akrone tornou-se a primeira casa relojoeira francesa a lançar um projeto via Kickstarter (K-01, setembro de 2015), inspirando o renascimento da relojoaria independente francesa. O nome vem do grego "achrone" ("fora do tempo") com o "K" referenciando os fundadores. A marca possui ateliê próprio em Nantes onde controla design, montagem e ajuste, usando movimentos Sellita, ETA, France Ébauches, Citizen e Seiko, e materiais como titânio, aço 316L, cerâmica e carbono. Mais de 100 projetos para o exército francês (ALAT, Legião Estrangeira) e aviação civil (Air France, Transavia) demonstram sua expertise. O modelo K-02 foi certificado "Tête de Vipère" e testado em mergulho recorde a 267m. | J33: C-02 Nérée (mergulho, muitas cores) / C-02 Héritage e Baby Héritage / C-02 Tactik Evo C-03 Horizon, Worldtimer, GMT e Carbon Fury (aviação, titânio e carbono) S-05 (cronógrafo meca-quartz) Históricos: K-01 (2015), K-02, K-03 GMT, K-04, K-05 Chronographe, C-04 | K33: https://akrone.fr/cdn/shop/files/akrone-logo-black.svg?v=1741343267
A34: Akura | B34: Reino Unido | C34: Dundee | D34: Microbrand escocesa com design inspirado nas Highlands; uso raro de bezel interno de bússola controlado por segunda coroa; tool watch acessível | E34: 2 | F34: 2700 | G34: akuratime.com | H34: @akuratime | I34: A Akura nasceu em novembro de 2017 em Dundee, Escócia, fundada pelo designer Philipp Schönfisch. O nome deriva do alemão "akkurat" (preciso), homenageando suas raízes. Após 18 meses de iteração com a comunidade relojoeira, lançou seu primeiro modelo, o Wayfarer, via Kickstarter em 2019 com preço promocional de £399. Inspirado nas Scottish Highlands, o Wayfarer combina caixa de aço 316L de 41mm, cristal de safira, resistência de 100m, movimento Miyota 9015 com rotor customizado e — diferencial raro — uma segunda coroa que controla bezel interno rotativo de bússola. ATENÇÃO: marca aparenta estar inativa após o Kickstarter inicial; verificar status antes de postar. | J34: Wayfarer (único modelo lançado, várias variações de cor)
A35: Alain Silberstein | B35: França | C35: Besançon | D35: Alta relojoaria de design Bauhaus com cores primárias (vermelho, azul, amarelo) e formas geométricas (triângulo, círculo, quadrado); marca encerrada em 2012, hoje vive em colaborações de luxo | E35: 5 | F35: 21000 | G35: marca encerrada em 2012; ver colaborações em louiserard.com, mbandf.com | H35: (sem perfil oficial; ver @louiserardwatches, @mbandf) | I35: Nascido em 1950 em Besançon, Alain Silberstein era arquiteto de interiores treinado em Paris quando, em 1987, apresentou seu primeiro relógio na feira de Basileia ao lado de pioneiros como George Daniels, Svend Andersen e Franck Muller. Em 1990 estabeleceu sua marca homônima, produzindo peças audaciosas com cores primárias e formas geométricas inspiradas em Kandinsky, Picasso e Miró. A marca fechou em 2012, mas seu legado se manteve vivo em colaborações com MB&F (HM2.2 Black Box em 2009, LM1 em 2016), Romain Jerome, Ressence (Carpe Diem) e, desde 2019, Louis Erard — cuja primeira parceria, o Régulateur, esgotou em horas e venceu o Red Dot Award 2021. A trilogia Le Triptyque (limitada a 178 peças cada) consolidou seu retorno como referência viva da relojoaria de design. | J35: Krono Bauhaus | Bolido | Marine GMT | Klok | Louis Erard x AS Régulateur / Le Triptyque | MB&F LM1 Silberstein | K35: https://watch-wiki.org/images/1/1d/Alain_Silberstein_Logo.jpg
A36: Albert Riele | B36: Suíça | C36: La Chaux-de-Fonds | D36: Marca suíça histórica (140+ anos) hoje pertencente ao grupo polonês R2 Trade, com estética clássica, movimentos Ronda/ETA/Sellita e preços acessíveis dentro do segmento Swiss Made | E36: 2 | F36: 3000 | G36: albertriele.ch | H36: @albertriele | I36: Em setembro de 1881, Rodolphe Albert Rielé registrou seu nome de família como marca em La Chaux-de-Fonds — coração da relojoaria suíça. Em 1894, mudanças nas leis de marcas suíças geraram o famoso acrônimo "RAR". Rielé já trabalhava como relojoeiro desde a década de 1860 e conquistou prêmios em exposições de relojoaria, com seus movimentos certificados "Bulletins 1ère Classe" pelos predecessores do COSC. Hoje, a Albert Riele faz parte do grupo polonês R2 Trade, especializado em joias e relógios, que também opera as marcas Bergstern, Aztorin, Elixa e AM:PM. Em 2016, celebrou seu 135º aniversário com a coleção comemorativa Family 1881, incluindo série limitada de 135 relógios de bolso mecânicos. A marca patrocina eventos de vela (World Match Racing Tour) e equestrianismo. | J36: Premiere (cronógrafo flagship) | Concerto | Gala (linha feminina) | Family 1881 | Challenger | K36: https://albertriele.ch/img/albert-riele.png
A37: Albishorn | B37: Suíça | C37: La Chaux-de-Fonds | D37: Manufatura suíça independente do conceito "Imaginary Vintage®" — relógios que parecem de uma era passada mas são novos, com movimentos próprios certificados COSC e produção em séries limitadas | E37: 5 | F37: 22000 | G37: albishorn-watches.ch | H37: @albishorn_watches | I37: A Albishorn foi fundada por Sébastien Chaulmontet e Fabien Collioud em La Chaux-de-Fonds, ambos com forte bagagem na alta relojoaria suíça. Chaulmontet foi Diretor de Inovação da Manufacture La Joux-Perret de 2008 a 2017, liderando a inovação das marcas Arnold & Son e Angelus, e atualmente é Head of Innovation and Marketing na Sellita Watch Co. Também é autor do livro "Chronograph for Collectors". A proposta é criar "Imaginary Vintage®" — relógios que se encaixam perfeitamente na história da relojoaria mas têm caráter próprio, como "elos perdidos" entre eras clássicas. O Type 10 (2024) é apresentado como o ancestral imaginário do Type 20 do exército francês. A marca já lançou colaboração com a Massena LAB (Maxigraph). Os preços (CHF 3.650-3.950) posicionam a marca no segmento independente de luxo, abaixo de competidores diretos. | J37: Type 10 Classic (1948 pilot monopusher) | Thundergraph Himalaya (1952 alpinist) | Marinagraph (1958 dive) | Maxigraph (com Massena LAB) | K37: https://albishorn-watches.ch/svg/logo.svg
A38: Alcadus | B38: Malásia | C38: Kuala Lumpur | D38: Microbrand malaia de design discreto e elegante com acabamento manual, garantia "Worry-Free" de 4 anos cobrindo até substituição de caixa, e revestimento anti-arranhão de 800 HV | E38: 2 | F38: 3500 | G38: alcadus.com | H38: @alcadus | I38: A Alcadus foi fundada em 2018 em Kuala Lumpur, Malásia, pelo entusiasta Yook Hong, que começou sua jornada modificando relógios Seiko antes de criar a marca. O nome combina o latim "altus" (elevado, nobre, profundo) com "cadence" (batida, ritmo do movimento mecânico). A proposta é oferecer relógios premium porém acessíveis com design discreto e elegante. A Quantra — quinta coleção da marca — usa movimento Hangzhou micro-rotor 5015A regulado a +/- 7s/dia, em caixa de 36mm com apenas 10,5mm de espessura, com preço de lançamento de US$ 635. O Voyager Worldtimer GMT vem com Miyota 9075 regulado in-house, caixa de 39mm, vidro de safira em formato "box" com 5 camadas de antirreflexo e resistência de 200m. Diferencial: garantia de 4 anos que cobre até substituição da caixa por danos de uso diário. | J38: Quantra (dress, Type 01/02/03) | Voyager Worldtimer GMT | Opus 39 V2 (dress diver) | Dromo (skin diver vintage) | K38: https://alcadus.com/wp-content/themes/moderno-child/assets/brand/alcadus-lockup-stacked-ink.png
A39: Alchemists | B39: Suíça | C39: Saignelégier | D39: Alta relojoaria com case em liga Cuprum 479 | F39: 1200000 | G39: alchemists.swiss | H39: @alchemists_watches | I39: Alchemists é uma jovem manufatura suíça independente que estreou no Baselworld 2019 com o Cu29 Chapter 1, finalista do GPHG 2019. A marca produz cerca de uma peça por mês, e seu diferencial é o material exclusivo "Cuprum 479" — uma liga patenteada de cobre, ouro e prata. O movimento manual feito in-house tem 51 rubis e reserva de 72 horas, com acabamento aprovado pelo lendário Philippe Dufour. Cada peça custa próximo de CHF 200.000. | J39: Cu29 Chapter 1
A40: Alessandro Baldieri | B40: Itália | C40: Roma | D40: Design italiano com cases robustos | E40: 1 | F40: 1500 | G40: bensontrade.com (revendedor) | H40: @alessandrobaldieri | I40: Alessandro Baldieri é um designer italiano formado em arquitetura e design de interiores em Los Angeles, conhecido por projetar residências de celebridades como Nicolas Cage e Lionel Richie. Em 2006 lançou sua linha de relógios sob o próprio nome, com design italiano contemporâneo, cases robustos (a partir de 44mm) e combinações ousadas de cores. Também é fundador da marca Trifoglio Italia. | J40: Seamonster (SM-46, Panarea), Magnum M-48, Skull Project, Retrospec, End of Time | K40: https://bensontrade.com/dynamic/brand_logos/alessandro-baldieri_1.png
...

Sheet Planilha1
C1: Marca
A2: Aaron BECSEI | aaronbecseiatelier | C2: 1776 Atelier
A3: ABINGER® | abingerwatches | C3: 2CAN
C4: 2LMX WATCHES
A5: ADDIESDIVE® | addiesdivewatches | C5: 3H Italia
A6: AEROTEC Watches | aerotecwatches | C6: 47 Zero
A7: AGELOCER ORIGINAL | agelocer_official | C7: 4N Watches
A8: ALEXANDRE MARTIN | alexandre.martin.watches | C8: 666 Barcelona
A9: Alterumwatchco | alterumwatchcompany | C9: 6B Watches
A10: Apiar | apiaruk | C10: 88 Rue Du Rhone
A11: Area Nostalgia | areanostalgiawatches | C11: A. Lange & Söhne
A12: Aubert & Ramel | aubert.ramel | C12: A. Manzoni & Fils
A13: Auriva Watches Montres Premium | aurivawatches | C13: AATOS
A14: Baltany watches | baltany_watches | C14: Abingdon
A15: Baume Watches | baumewatches | C15: About Vintage
A16: Blessington Watches | blessington.watches | C16: Accutron
... A24: D1 Milano | d1milano | C24: Aesop
C25: Aether
A26: De Marquee | demarqueewatch | C26: Aethia
A27: Delhi Watch Company | delhiwatchcompany | C27: Airain
A28: Diatom Watches | diatomwatches | C28: Aision
A29: echo/neutra | echo_neutra | C29: Aittokoski Timecrafts Fractalis
A30: EDIFICE OFFICIAL | casioedifice_sg | C30: Akerfalk
A31: EI8HT | ei8ht_watches | C31: Akhor
A32: Elgé Watches | elge_fh | C32: Akrivia
C33: Akrone
A34: EONIQ Watches | Designed & Made in HK | eoniqatelier | C34: Akura
A35: Forward Watch Co. | forwardwatchco | C35: Alain Silberstein
A36: Fukushima Watch Company | fukushima_watch.co | C36: Albert Riele
A37: Galo Watches | galowatches | C37: Albishorn
A38: Grandeur | grandeur | C38: Alcadus
A39: GRØNE Oldenzaal | groneoldenzaal | C39: Alchemists
A40: GUSTAVE & cie | gustave_et_cie | C40: Alessandro Baldieri
A41: Harriot 해리엇 | Korean Watch | harriotwatches | C41: Alessandro Staffetta (AS)
A42: Havid Nagan®️ | havidnagan | C42: Alex Benlo
A43: HGP Watches | hgp_hommes_grenouilles_paris | C43: Alexander James
A44: hodinkee | hodinkee | C44: Alexander Shorokhoff
C45: Alexandre Meerson
C46: Alexis Garin
C47: AleXora
...

Sheet Relógios
A1: Marca | B1: Modelo | C1: Relógio | E1: Características
A2: Cuervo y Sobrinos | B2: Flechazo - 3142.1G | C2: https://cdn.sanity.io/images/qpozxwu2/cys-backend/e80d691c0ef40528645ef84391fec7a1d7476ae3-2953x5315.png
A3: Cuervo y Sobrinos | B3: Historiador Flameante - 3130.1FGR | C3: https://www.cuervoysobrinos.com/585-large_default/flameante.jpg
A4: Pequignet | B4: Royale 300 - 9050343 | C4: https://static.wixstatic.com/media/ee021f_fc006302d3d74af5a0ed2e25330dd741~mv2.png/v1/fill/w_800,h_1218,al_c/ee021f_fc006302d3d74af5a0ed2e25330dd741~mv2.png
A5: Pequignet | B5: Royale 300 - 9050473/36 | C5: https://static.wixstatic.com/media/ee021f_7cc9698edfdc4d729da31bd5f6bb00ff~mv2.png/v1/fill/w_800,h_1218,al_c/ee021f_7cc9698edfdc4d729da31bd5f6bb00ff~mv2.png
A6: Rado | B6: Centrix - R30130152 | C6: https://m.media-amazon.com/images/I/61ziyN9tGfL._AC_UF1000,1000_QL80_.jpg
A7: Rado | B7: Coupole - R22895165 | C7: http://cdn.shopify.com/s/files/1/0261/8900/4880/products/R22895165_1200x1200.jpg?v=1627044818
A8: Rado | B8: DiaMaster - 604.0070.3 | C8: https://www.uhrenschmuck24.ch/media/catalog/product/img/1/image/1080x1080/r/a/rado-diamaster-xxl-automatik-chronograph-7612819048369-1.jpg
A9: Rado | B9: DiaMaster - R14053106 | C9: https://www.rado.com/media/catalog/product/cache/af21745092e03eab5206bbb4f15452fb/r/g/rgb_cat_diamaster_773_6053_3_410_3.png
A10: Rado | B10: DiaMaster - R14070176 | C10: https://http2.mlstatic.com/D_NQ_NP_838357-MLB31670849222_082019-W.jpg
A11: Rado | B11: DiaMaster - R14129206 | C11: https://watchdreamer.com/sites/default/files/2021-09/R14129206_.png
A12: Rado | B12: HyperChrome - R32042305 | C12: https://www.hodinarstvibechyne.cz/res/crc-355981002/products/images/1920x1920/noenl/693678-r32042305-s.jpg
A13: Rado | B13: HyperChrome Captain Cook - R32145208 | C13: https://www.gregoryjewellers.com.au/wp-content/uploads/2022/08/RADO_r32145208_steel-43mm.jpg
... A68: Revue Thommen | B68: Aviator - 17000.6137 | C68: http://cdn.shopify.com/s/files/1/0614/9963/8003/products/revue-thommen-17000_6137-761175117502-chronolounge.png?v=1667874496
A69: Revue Thommen | B69: Aviator - 17000.6532 | C69: https://webassets.ashford.com/images/web/revue_thommen/17000.6532_FXA.jpg | D69: https://dbnext.watch-experts.net/api/images/watch/scale/400/5db05de18a4c9-cgk204-curare.jpg
A70: Revue Thommen | B70: Aviator - 17000.6535 | C70: https://cdn03.plentymarkets.com/ciw7a3ibeo67/item/images/8963507/full/Revue-Thommen-Herren-Armbanduhr-Automatic--Aviator-42-mm-Chronograph--Tachymeter-Armband-Leather-17000-6535-17000-6535_1.jpg
A71: Revue Thommen | B71: Aviator - 17000.6557 | C71: https://i.ebayimg.com/images/g/8EsAAOSwbdNfvDBr/s-l1600.jpg
A72: Revue Thommen | B72: Day Pointer - 10012.2512 | C72: https://cdn03.plentymarkets.com/ciw7a3ibeo67/item/images/8961773/full/Revue-Thommen-Herren-Armbanduhr-Automatik-DATE-POINTER-10012-2512-XLarge-10012-2512-Rev.jpg
A73: Revue Thommen | B73: Day Pointer - 10012.2537 | C73: https://www.kechiq.com/public/images/products/fdb43871-d38a-48b1-9629-ef8b414e4a44.jpg
A74: Revue Thommen | B74: Diver - 17030.6121 | C74: https://webassets.ashford.com/images/web/revue_thommen/17030.6121_FXA.jpg
A75: Revue Thommen | B75: Diver - 17030.6123 | C75: https://cdn2.jomashop.com/media/catalog/product/r/e/revue-thommen-diver-chronograph-automatic-blue-dial-mens-watch-170306123-170306123.jpg
A76: Revue Thommen | B76: Diver - 17030.6535 | C76: https://image.goxip.com/1pRGIr-zhaQIH9-UDZV0lRE9bFE=/fit-in/500x500/filters:format(jpg):quality(80):fill(white)/http:%2F%2Fres.cloudinary.com%2Fdjtnxo4ow%2Fimage%2Fprivate%2Fs--_F62uhCp--%2Fv1646357576%2Fimage1%2Fgawz48efkg2eyuzaattg.jpg%3Fdate=2022-03-03
A77: Revue Thommen | B77: Diver - 17571.2577 | C77: https://cdn.shopify.com/s/files/1/0552/3374/0989/products/17571.2537_250x250@2x.jpg?v=1649706958
A78: Revue Thommen | B78: Diver - 17571.2776 | C78: https://i.ebayimg.com/images/g/56AAAOSwL2JjvYwG/s-l1600.jpg
A79: Revue Thommen | B79: Specialities Moonphase - 16066.2532 | C79: https://www.gemnation.com/images/watches/Revu/16066.2532_ZM.jpg
A80: Revue Thommen | B80: Specialities Moonphase - 16066.2537 | C80: https://swissluxurywatches.ch/wp-content/uploads/2017/12/16066.2537_ZM.jpg
A81: Richard Mille | B81: RM21-01 - Tourbillon Aerodyne Limited Edition | C81: https://swisswatches-magazine.de/wp-content/uploads/sites/3/2021/04/Richard-Mille-RM-21-01-Tourbillon-Aerodyne-Titelbild.jpg
... A115: Tag Heuer | B115: Carrera Calibre 16 Lewis Hamilton Limited Edition - CV201MBA0794 | C115: https://cdn.trusted.com/images/20000102/17938_org.jpg
A116: Tag Heuer | B116: Carrera Calibre 16 Senna Edition - CBB2010.BA0906 | C116: https://cdn.shopify.com/s/files/1/0125/7792/products/TAG-397_TAG_Heuer_Watch_Carrera_Chronograph_Senna_Limited_CBB2010.BA0906.jpg?v=1435766803 | D116: https://cdn2.jomashop.com/media/catalog/product/t/a/tag-heuer-carrera-chronograph-automatic-mens-watch-cv2a1abba0738-cv2a1abba0738.jpg
A117: Tag Heuer | B117: Carrera Calibre 1887 - CAR2111.FC6291 | C117: https://www.tagheuer.com/on/demandware.static/-/Sites-tagheuer-master/default/dwba39e794/TAG_Heuer_Carrera/CAR2111_FC6291/CAR2111_FC6291_000913.png?impolicy=resizeTrim&width=884&height=1106
A118: Tag Heuer | B118: Carrera Calibre 1887 - CAR2C12.FC6327 | C118: https://www.tagheuer.com/on/demandware.static/-/Sites-tagheuer-master/default/dwa7e6c646/TAG_Heuer_Carrera/CAR2C12.FC6327/CAR2C12.FC6327_0913.png | D118: https://cdn.trusted.com/images/20000102/16910_org.jpg
